Workbook

Sheet Hoja 1
A2: Ingresos | G2: 70 tortas mensuales
B3: Año 1 | C3: Año 2 | D3: Año 3 | E3: Año 4 | G3: Precio de venta: aumento 15% anual
A4: Cantidades Vendidas | B4: 840 | C4: 900 | D4: 960 | E4: 1150 | G4: 0.6
A5: Precio de Venta | B5: 35000 | C5: =(B5*(1+$G$4)) -> 56000 | D5: =(C5*(1+$G$4)) -> 89600 | E5: =(D5*(1+$G$4)) -> 143360
A6: Total Ingreso | B6: =(B4*B5) -> 29400000 | C6: =(C4*C5) -> 50400000 | D6: =(D4*D5) -> 86016000 | E6: =(E4*E5) -> 164864000
A9: Egresos
B10: Año 1 | C10: Año 2 | D10: Año 3 | E10: Año 4 | G10: =(455000*12) -> 5460000
A11: Alquiler | B11: =-$G$10 -> -5460000 | C11: =-$G$10 -> -5460000 | D11: =-$G$10 -> -5460000 | E11: =-$G$10 -> -5460000
A12: Proveedores/Servicios | B12: -300000 | C12: -400000 | D12: -400000 | E12: -400000
A13: Sueldos | B13: =-(G13) -> -1500000 | C13: =(B13*(1+$H$13)) -> -2100000 | D13: =(C13*(1+$H$13)) -> -2940000 | E13: =(D13*(1+$H$13)) -> -4116000 | G13: =(500000+600000+400000) -> 1500000 | H13: 0.4
A14: Total Egresos anuales | B14: =SUM(B11:B13) -> -7260000 | C14: =SUM(C11:C13) -> -7960000 | D14: =SUM(D11:D13) -> -8800000 | E14: =SUM(E11:E13) -> -9976000
B17: 0 | C17: 1 | D17: 2 | E17: 3 | F17: 4
A18: II | B18: -5390000
A19: Ingresos | C19: =(B6) -> 29400000 | D19: =(C6) -> 50400000 | E19: =(D6) -> 86016000 | F19: =(E6) -> 164864000 | H19: 5390000 | I19: 4 | J19: =-(H19/I19) -> -1347500
A20: Egresos | C20: =(B14) -> -7260000 | D20: =(C14) -> -7960000 | E20: =(D14) -> -8800000 | F20: =(E14) -> -9976000
A21: UAIT | C21: =(C19+C20) -> 22140000 | D21: =(D19+D20) -> 42440000 | E21: =(E19+E20) -> 77216000 | F21: =(F19+F20) -> 154888000 | H21: 0.35
A22: Amortizaciones | C22: =(J19) -> -1347500 | D22: =(J19) -> -1347500 | E22: =(J19) -> -1347500 | F22: =(J19) -> -1347500
A23: Base imponible | C23: =(C21+C22) -> 20792500 | D23: =(D21+D22) -> 41092500 | E23: =(E21+E22) -> 75868500 | F23: =(F21+F22) -> 153540500
A24: IIGG | C24: =-(C23*$H$21) -> -7277375 | D24: =-(D23*$H$21) -> -14382375 | E24: =-(E23*$H$21) -> -26553975 | F24: =-(F23*$H$21) -> -53739175
A25: Amortizaciones | C25: =-($J$19) -> 1347500 | D25: =-($J$19) -> 1347500 | E25: =-($J$19) -> 1347500 | F25: =-($J$19) -> 1347500
A26: Capital de trabajo | B26: -1310000 | F26: =(1310000) -> 1310000
A27: FFON | C27: =(C23+C24+C25+C26) -> 14862625 | D27: =(D23+D24+D25+D26) -> 28057625 | E27: =(E23+E24+E25+E26) -> 50662025 | F27: =(F23+F24+F25+F26) -> 102458825
A28: Capital | B28: =(B41) -> 2156000
A29: Cuota de amortización | C29: =-(C41) -> -248490.87 | D29: =-C42 -> -385160.85 | E29: =-C43 -> -596999.32 | F29: =-C44 -> -925348.95
A30: Cuota de interés | C30: =-(D41) -> -1185800 | D30: =-D43 -> -837291.55 | E30: =-D43 -> -837291.55 | F30: =-D44 -> -508941.92
A31: Efecto impositivo | C31: =-(C30*$H$21) -> 415030 | D31: =-(D30*$H$21) -> 293052.04 | E31: =-(E30*$H$21) -> 293052.04 | F31: =-(F30*$H$21) -> 178129.67
A32: FFFN | B32: =(B18+B28) -> -3234000 | C32: =SUM(C29:C31) -> -1019260.9 | D32: =SUM(D29:D31) -> -929400.36 | E32: =SUM(E29:E31) -> -1141238.8 | F32: =SUM(F29:F31) -> -1256161.2
A33: FFO y FFFN | B33: =(B32) -> -3234000 | C33: =(C27+C32) -> 13843364 | D33: =(D27+D32) -> 27128225 | E33: =(E27+E32) -> 49520786 | F33: =(F27+F32) -> 1.0120266e+08
A34: FFD | B34: =B33 -> -3234000 | C34: =C33/(1+$G$34)^C17 -> 8389917.7 | D34: =D33/(1+$G$34)^D17 -> 9964453.5 | E34: =E33/(1+$G$34)^E17 -> 11023911 | F34: =F33/(1+$G$34)^F17 -> 13653883 | G34: 0.65
A35: VAN | B35: =(B34+C34+D34+E34+F34) -> 39798165
A36: TIR | B36: =IRR(B34:F34) -> 2.7417854
A37: PRD | B37: 1 año, 7 meses y 11 dias
A40: Periodo | B40: Deuda al Inicio | C40: C.de Amortiz. | D40: C. de Interes | E40: C. Total | F40: D. al cierre
A41: 1 | B41: =(H42*I42) -> 2156000 | C41: =(E41-D41) -> 248490.87 | D41: =(B41*$H$41) -> 1185800 | E41: =PMT($H$41,$H$45,-$B$41) -> 1434290.9 | F41: =(B41-C41) -> 1907509.1 | H41: 0.55
A42: 2 | B42: =(F41) -> 1907509.1 | C42: =(E42-D42) -> 385160.85 | D42: =(B42*$H$41) -> 1049130 | E42: =PMT($H$41,$H$45,-$B$41) -> 1434290.9 | F42: =(F41-C42) -> 1522348.3 | H42: 5390000 | I42: 0.4
A43: 3 | B43: =(F42) -> 1522348.3 | C43: =(E43-D43) -> 596999.32 | D43: =(B43*$H$41) -> 837291.55 | E43: =PMT($H$41,$H$45,-$B$41) -> 1434290.9 | F43: =(F42-C43) -> 925348.95 | H43: 1355020.9
A44: 4 | B44: =(F43) -> 925348.95 | C44: =(E44-D44) -> 925348.95 | D44: =(B44*$H$41) -> 508941.92 | E44: =PMT($H$41,$H$45,-$B$41) -> 1434290.9 | F44: =(F43-C44) -> -1.1641532e-10
H45: 4

Sheet Analisis de sensibilidad
A1: Flujo de fondo original
B2: Año 0 | C2: 1 | D2: 2 | E2: 3 | F2: 4
A3: II | B3: -5390000
A4: Ingresos | C4: 29400000 | D4: 50400000 | E4: 86016000 | F4: 164864000
A5: Egresos | C5: -7260000 | D5: -7960000 | E5: -8800000 | F5: -9976000
A6: UAIT | C6: 22140000 | D6: 42440000 | E6: 77216000 | F6: 154888000
A7: Amortizaciones | C7: -1347500 | D7: -1078000 | E7: -1078000 | F7: -1078000
A8: Base imponible | C8: 21062000 | D8: 41362000 | E8: 76138000 | F8: 153810000
A9: IIGG | C9: -7371700 | D9: -14476700 | E9: -26648300 | F9: -53833500
A10: Amortizaciones | C10: 1078000 | D10: 1078000 | E10: 1078000 | F10: 1078000
A11: Capital de trabajo | B11: -1310000 | F11: 1310000
A12: FFON | C12: 14768300 | D12: 27963300 | E12: 50567700 | F12: 102364500
A13: Capital | B13: 2156000
A14: Cuota de amortización | C14: -248490.87 | D14: -385160.85 | E14: -596999.32 | F14: -925348.95
A15: Cuota de interés | C15: -1185800 | D15: -837291.55 | E15: -837291.55 | F15: -508941.92
A16: Efecto impositivo | C16: 415030 | D16: 293052.04 | E16: 293052.04 | F16: 178129.67
A17: FFFN | B17: -3234000 | C17: -1019260.9 | D17: -929400.36 | E17: -1141238.8 | F17: -1256161.2
A18: FFO y FFFN | B18: -3234000 | C18: 13749039 | D18: 27033900 | E18: 49426461 | F18: 1.0110834e+08
A19: FFD | B19: -3234000 | C19: 13749039 | D19: 27033900 | E19: 49426461 | F19: 1.0110834e+08
A20: VAN
A21: TIR
A22: Variacion de los Egresos 10% aumento en Sueldos
B24: Año 0 | C24: 1 | D24: 2 | E24: 3 | F24: 4
A25: II | B25: -5390000
A26: Ingresos | C26: 29400000 | D26: 50400000 | E26: 86016000 | F26: 164864000
A27: Egresos | C27: =J32 -> -7410000 | D27: =K32 -> -8170000 | E27: =L32 -> -9094000 | F27: =M32 -> -10387600 | G27: 0.1 | I27: Egresos +10% Sueldos
A28: UAIT | C28: =C26+C27 -> 21990000 | D28: =D26+D27 -> 42230000 | E28: =E26+E27 -> 76922000 | F28: =F26+F27 -> 154476400 | J28: Año 1 | K28: Año 2 | L28: Año 3 | M28: Año 4
A29: Amortizaciones | C29: -1347500 | D29: -1347500 | E29: -1347500 | F29: -1347500 | I29: Alquiler | J29: -5460000 | K29: -5460000 | L29: -5460000 | M29: -5460000
A30: Base imponible | C30: =C28+C29 -> 20642500 | D30: =D28+D29 -> 40882500 | E30: =E28+E29 -> 75574500 | F30: =F28+F29 -> 153128900 | I30: Proveedores/Servicios | J30: -300000 | K30: -400000 | L30: -400000 | M30: -400000
A31: IIGG | C31: =-C30*$G$31 -> -7224875 | D31: =-D30*$G$31 -> -14308875 | E31: =-E30*$G$31 -> -26451075 | F31: =-F30*$G$31 -> -53595115 | G31: 0.35 | I31: Sueldos | J31: ='Hoja 1'!B13*(1+$G$27) -> -1650000 | K31: ='Hoja 1'!C13*(1+$G$27) -> -2310000 | L31: ='Hoja 1'!D13*(1+$G$27) -> -3234000 | M31: ='Hoja 1'!E13*(1+$G$27) -> -4527600
A32: Amortizaciones | C32: 1347500 | D32: 1347500 | E32: 1347500 | F32: 1347500 | I32: Total Egresos anuales | J32: =J29+J30+J31 -> -7410000 | K32: =K29+K30+K31 -> -8170000 | L32: =L29+L30+L31 -> -9094000 | M32: =M29+M30+M31 -> -10387600
A33: Capital de trabajo | B33: -1310000 | F33: 1310000
A34: FFON | C34: =C30+C31+C32 -> 14765125 | D34: =D30+D31+D32 -> 27921125 | E34: =E30+E31+E32 -> 50470925 | F34: =F30+F31+F32+F33 -> 102191285 | I34: Egresos - 10% Sueldos
A35: Capital | B35: 2156000 | J35: Año 1 | K35: Año 2 | L35: Año 3 | M35: Año 4
A36: Cuota de amortización | C36: -248490.87 | D36: -385160.85 | E36: -596999.32 | F36: -925348.95 | I36: Alquiler | J36: -5460000 | K36: -5460000 | L36: -5460000 | M36: -5460000
A37: Cuota de interés | C37: -1185800 | D37: -837291.55 | E37: -837291.55 | F37: -508941.92 | I37: Proveedores/Servicios | J37: -300000 | K37: -400000 | L37: -400000 | M37: -400000
A38: Efecto impositivo | C38: 415030 | D38: 293052.04 | E38: 293052.04 | F38: 178129.67 | I38: Sueldos | J38: ='Hoja 1'!B13*(1-$G$27) -> -1350000 | K38: ='Hoja 1'!C13*(1-$G$27) -> -1890000 | L38: ='Hoja 1'!D13*(1-$G$27) -> -2646000 | M38: ='Hoja 1'!E13*(1-$G$27) -> -3704400
A39: FFFN | B39: -3234000 | C39: -1019260.9 | D39: -929400.36 | E39: -1141238.8 | F39: -1256161.2 | I39: Total Egresos anuales | J39: =J36+J37+J38 -> -7110000 | K39: =K36+K37+K38 -> -7750000 | L39: =L36+L37+L38 -> -8506000 | M39: =M36+M37+M38 -> -9564400
A40: FFO y FFFN | B40: -3234000 | C40: =C34+C39 -> 13745864 | D40: =D34+D39 -> 26991725 | E40: =E34+E39 -> 49329686 | F40: =F34+F39 -> 1.0093512e+08
A41: FFD | B41: -3234000 | C41: =C40/(1+$G$41)^C24 -> 8330826.7 | D41: =D40/(1+$G$41)^D24 -> 9914315.8 | E41: =E40/(1+$G$41)^E24 -> 10981370 | F41: =F40/(1+$G$41)^F24 -> 13617787 | G41: 0.65
...

Sheet Cuantificaciòn de necesidades
A2: Costo | B2: 17000
A3: Unidades | B3: 1500
A4: Compras | B4: =B2*B3 -> 25500000
A6: Dias de cobro | B6: 20 | C6: CCE: | D6: =B6+B7-B8 -> 19
A7: Stock inventario | B7: 14 | D7: 360 | E7: dias
A8: Dias de pago | B8: 15
A10: Necesidad de Capital de trabajo: | C10: =B4*(D6/D7) -> 1345833.3
